Workbook

Sheet Inputs
A1: Key | B1: Category | C1: Assumption | D1: Unit | E1: Conservative | F1: Base | G1: Optimistic | H1: Notes / source
A2: starting_cash | B2: Funding | C2: Starting cash balance | D2: $ | E2: 10000 | F2: 25000 | G2: 50000 | H2: Cash available at model start; scenario planning assumption.
A3: launch_active_users | B3: Revenue - membership | C3: Month 1 active users | D3: users | E3: 50 | F3: 150 | G3: 300 | H3: Driven by docs/strategy/growth-playbook.md community launch actions.
A4: monthly_active_growth | B4: Revenue - membership | C4: Monthly active-user growth | D4: % | E4: 0.08 | F4: 0.15 | G4: 0.22 | H4: Three distinct trajectories from CMO community growth playbook paths.
A5: paid_conversion | B5: Revenue - membership | C5: Paid conversion rate | D5: % | E5: 0.04 | F5: 0.07 | G5: 0.1 | H5: Membership, verification, safety, access value per AGENTS.md/agent.md.
A6: monthly_subscription_price | B6: Revenue - membership | C6: Average monthly paid membership price | D6: $/paid member | E6: 9 | F6: 12 | G6: 15 | H6: Square checkout product assumption; update with live catalog when finalized.
A7: events_month1 | B7: Revenue - events | C7: Month 1 collaborative events | D7: events | E7: 1 | F7: 2 | G7: 4 | H7: CMO growth playbook days 5-14: collaborative events and recurring calendars.
A8: event_growth | B8: Revenue - events | C8: Monthly event volume growth | D8: % | E8: 0.05 | F8: 0.1 | G8: 0.14 | H8: Growth playbook partnership scaling assumption.
A9: avg_event_revenue | B9: Revenue - events | C9: Average gross revenue per event | D9: $/event | E9: 200 | F9: 350 | G9: 600 | H9: Commercial consideration / partnership-fee path from growth playbook.
A10: partner_fee_per_event | B10: Cost - events | C10: Average partner fee per event | D10: $/event | E10: 75 | F10: 125 | G10: 200 | H10: Host/partner commercial consideration from growth playbook lines 146-154.
A11: services_rev_month1 | B11: Revenue - automation | C11: Month 1 automation/services revenue | D11: $ | E11: 750 | F11: 2000 | G11: 5000 | H11: CMO proposal/cold-email playbook in paperclip/agents/cmo-marketing.md.
A12: services_rev_growth | B12: Revenue - automation | C12: Monthly automation/services revenue growth | D12: % | E12: 0.05 | F12: 0.08 | G12: 0.1 | H12: Lead-gen/proposal conversion ramp; update with CRM data.
A13: merch_start_month | B13: Revenue - merch | C13: Merch starts in month | D13: month # | E13: 10 | F13: 7 | G13: 5 | H13: DAO architecture Track 3 merchandise path.
... A30: cogs_per_active_member | B30: Cost - variable | C30: Per-active-user platform variable cost | D30: $/active user/mo | E30: 0.05 | F30: 0.08 | G30: 0.12 | H30: Messaging/moderation/storage variable cost assumption.

Sheet Monthly Model
A1: Scenario | B1: Metric | C1: M01 | D1: M02 | E1: M03 | F1: M04 | G1: M05 | H1: M06 | I1: M07 | J1: M08 | K1: M09 | L1: M10 | M1: M11 | N1: M12 | O1: M13 | P1: M14 | Q1: M15 | R1: M16 | S1: M17 | T1: M18 | U1: M19 | V1: M20 | W1: M21 | X1: M22 | Y1: M23 | Z1: M24 | AA1: M25 | AB1: M26 | AC1: M27 | AD1: M28 | AE1: M29 | AF1: M30 | AG1: M31 | AH1: M32 | AI1: M33 | AJ1: M34 | AK1: M35 | AL1: M36
A2: Conservative | B2: Active members | C2: =Inputs!$D$3*(1+Inputs!$D$4)^(1-1) | D2: =Inputs!$D$3*(1+Inputs!$D$4)^(2-1) | E2: =Inputs!$D$3*(1+Inputs!$D$4)^(3-1) | F2: =Inputs!$D$3*(1+Inputs!$D$4)^(4-1) | G2: =Inputs!$D$3*(1+Inputs!$D$4)^(5-1) | H2: =Inputs!$D$3*(1+Inputs!$D$4)^(6-1) | I2: =Inputs!$D$3*(1+Inputs!$D$4)^(7-1) | J2: =Inputs!$D$3*(1+Inputs!$D$4)^(8-1) | K2: =Inputs!$D$3*(1+Inputs!$D$4)^(9-1) | L2: =Inputs!$D$3*(1+Inputs!$D$4)^(10-1) | M2: =Inputs!$D$3*(1+Inputs!$D$4)^(11-1) | N2: =Inputs!$D$3*(1+Inputs!$D$4)^(12-1) | O2: =Inputs!$D$3*(1+Inputs!$D$4)^(13-1) | P2: =Inputs!$D$3*(1+Inputs!$D$4)^(14-1) | Q2: =Inputs!$D$3*(1+Inputs!$D$4)^(15-1) | R2: =Inputs!$D$3*(1+Inputs!$D$4)^(16-1) | S2: =Inputs!$D$3*(1+Inputs!$D$4)^(17-1) | T2: =Inputs!$D$3*(1+Inputs!$D$4)^(18-1) | U2: =Inputs!$D$3*(1+Inputs!$D$4)^(19-1) | V2: =Inputs!$D$3*(1+Inputs!$D$4)^(20-1) | W2: =Inputs!$D$3*(1+Inputs!$D$4)^(21-1) | X2: =Inputs!$D$3*(1+Inputs!$D$4)^(22-1) | Y2: =Inputs!$D$3*(1+Inputs!$D$4)^(23-1) | Z2: =Inputs!$D$3*(1+Inputs!$D$4)^(24-1) | AA2: =Inputs!$D$3*(1+Inputs!$D$4)^(25-1) | AB2: =Inputs!$D$3*(1+Inputs!$D$4)^(26-1) | AC2: =Inputs!$D$3*(1+Inputs!$D$4)^(27-1) | AD2: =Inputs!$D$3*(1+Inputs!$D$4)^(28-1) | AE2: =Inputs!$D$3*(1+Inputs!$D$4)^(29-1) | AF2: =Inputs!$D$3*(1+Inputs!$D$4)^(30-1) | AG2: =Inputs!$D$3*(1+Inputs!$D$4)^(31-1) | AH2: =Inputs!$D$3*(1+Inputs!$D$4)^(32-1) | AI2: =Inputs!$D$3*(1+Inputs!$D$4)^(33-1) | AJ2: =Inputs!$D$3*(1+Inputs!$D$4)^(34-1) | AK2: =Inputs!$D$3*(1+Inputs!$D$4)^(35-1) | AL2: =Inputs!$D$3*(1+Inputs!$D$4)^(36-1)
A3: Conservative | B3: Paid members | C3: =C2*Inputs!$D$5 | D3: =D2*Inputs!$D$5 | E3: =E2*Inputs!$D$5 | F3: =F2*Inputs!$D$5 | G3: =G2*Inputs!$D$5 | H3: =H2*Inputs!$D$5 | I3: =I2*Inputs!$D$5 | J3: =J2*Inputs!$D$5 | ... AL3: =AL2*Inputs!$D$5
A4: Conservative | B4: Membership revenue | C4: =C3*Inputs!$D$6 | D4: =D3*Inputs!$D$6 | E4: =E3*Inputs!$D$6 | F4: =F3*Inputs!$D$6 | G4: =G3*Inputs!$D$6 | H4: =H3*Inputs!$D$6 | I4: =I3*Inputs!$D$6 | J4: =J3*Inputs!$D$6 | ... AL4: =AL3*Inputs!$D$6
A5: Conservative | B5: Collaborative events | C5: =Inputs!$D$7*(1+Inputs!$D$8)^(1-1) | D5: =Inputs!$D$7*(1+Inputs!$D$8)^(2-1) | E5: =Inputs!$D$7*(1+Inputs!$D$8)^(3-1) | F5: =Inputs!$D$7*(1+Inputs!$D$8)^(4-1) | G5: =Inputs!$D$7*(1+Inputs!$D$8)^(5-1) | H5: =Inputs!$D$7*(1+Inputs!$D$8)^(6-1) | I5: =Inputs!$D$7*(1+Inputs!$D$8)^(7-1) | J5: =Inputs!$D$7*(1+Inputs!$D$8)^(8-1) | K5: =Inputs!$D$7*(1+Inputs!$D$8)^(9-1) | L5: =Inputs!$D$7*(1+Inputs!$D$8)^(10-1) | M5: =Inputs!$D$7*(1+Inputs!$D$8)^(11-1) | N5: =Inputs!$D$7*(1+Inputs!$D$8)^(12-1) | O5: =Inputs!$D$7*(1+Inputs!$D$8)^(13-1) | P5: =Inputs!$D$7*(1+Inputs!$D$8)^(14-1) | Q5: =Inputs!$D$7*(1+Inputs!$D$8)^(15-1) | R5: =Inputs!$D$7*(1+Inputs!$D$8)^(16-1) | S5: =Inputs!$D$7*(1+Inputs!$D$8)^(17-1) | T5: =Inputs!$D$7*(1+Inputs!$D$8)^(18-1) | U5: =Inputs!$D$7*(1+Inputs!$D$8)^(19-1) | V5: =Inputs!$D$7*(1+Inputs!$D$8)^(20-1) | W5: =Inputs!$D$7*(1+Inputs!$D$8)^(21-1) | X5: =Inputs!$D$7*(1+Inputs!$D$8)^(22-1) | Y5: =Inputs!$D$7*(1+Inputs!$D$8)^(23-1) | Z5: =Inputs!$D$7*(1+Inputs!$D$8)^(24-1) | AA5: =Inputs!$D$7*(1+Inputs!$D$8)^(25-1) | AB5: =Inputs!$D$7*(1+Inputs!$D$8)^(26-1) | AC5: =Inputs!$D$7*(1+Inputs!$D$8)^(27-1) | AD5: =Inputs!$D$7*(1+Inputs!$D$8)^(28-1) | AE5: =Inputs!$D$7*(1+Inputs!$D$8)^(29-1) | AF5: =Inputs!$D$7*(1+Inputs!$D$8)^(30-1) | AG5: =Inputs!$D$7*(1+Inputs!$D$8)^(31-1) | AH5: =Inputs!$D$7*(1+Inputs!$D$8)^(32-1) | AI5: =Inputs!$D$7*(1+Inputs!$D$8)^(33-1) | AJ5: =Inputs!$D$7*(1+Inputs!$D$8)^(34-1) | AK5: =Inputs!$D$7*(1+Inputs!$D$8)^(35-1) | AL5: =Inputs!$D$7*(1+Inputs!$D$8)^(36-1)
A6: Conservative | B6: Event revenue | C6: =C5*Inputs!$D$9 | D6: =D5*Inputs!$D$9 | E6: =E5*Inputs!$D$9 | F6: =F5*Inputs!$D$9 | G6: =G5*Inputs!$D$9 | H6: =H5*Inputs!$D$9 | I6: =I5*Inputs!$D$9 | J6: =J5*Inputs!$D$9 | ... AL6: =AL5*Inputs!$D$9
A7: Conservative | B7: Automation/services revenue | C7: =Inputs!$D$11*(1+Inputs!$D$12)^(1-1) | D7: =Inputs!$D$11*(1+Inputs!$D$12)^(2-1) | E7: =Inputs!$D$11*(1+Inputs!$D$12)^(3-1) | F7: =Inputs!$D$11*(1+Inputs!$D$12)^(4-1) | G7: =Inputs!$D$11*(1+Inputs!$D$12)^(5-1) | H7: =Inputs!$D$11*(1+Inputs!$D$12)^(6-1) | I7: =Inputs!$D$11*(1+Inputs!$D$12)^(7-1) | J7: =Inputs!$D$11*(1+Inputs!$D$12)^(8-1) | K7: =Inputs!$D$11*(1+Inputs!$D$12)^(9-1) | L7: =Inputs!$D$11*(1+Inputs!$D$12)^(10-1) | M7: =Inputs!$D$11*(1+Inputs!$D$12)^(11-1) | N7: =Inputs!$D$11*(1+Inputs!$D$12)^(12-1) | O7: =Inputs!$D$11*(1+Inputs!$D$12)^(13-1) | P7: =Inputs!$D$11*(1+Inputs!$D$12)^(14-1) | Q7: =Inputs!$D$11*(1+Inputs!$D$12)^(15-1) | R7: =Inputs!$D$11*(1+Inputs!$D$12)^(16-1) | S7: =Inputs!$D$11*(1+Inputs!$D$12)^(17-1) | T7: =Inputs!$D$11*(1+Inputs!$D$12)^(18-1) | U7: =Inputs!$D$11*(1+Inputs!$D$12)^(19-1) | V7: =Inputs!$D$11*(1+Inputs!$D$12)^(20-1) | W7: =Inputs!$D$11*(1+Inputs!$D$12)^(21-1) | X7: =Inputs!$D$11*(1+Inputs!$D$12)^(22-1) | Y7: =Inputs!$D$11*(1+Inputs!$D$12)^(23-1) | Z7: =Inputs!$D$11*(1+Inputs!$D$12)^(24-1) | AA7: =Inputs!$D$11*(1+Inputs!$D$12)^(25-1) | AB7: =Inputs!$D$11*(1+Inputs!$D$12)^(26-1) | AC7: =Inputs!$D$11*(1+Inputs!$D$12)^(27-1) | AD7: =Inputs!$D$11*(1+Inputs!$D$12)^(28-1) | AE7: =Inputs!$D$11*(1+Inputs!$D$12)^(29-1) | AF7: =Inputs!$D$11*(1+Inputs!$D$12)^(30-1) | AG7: =Inputs!$D$11*(1+Inputs!$D$12)^(31-1) | AH7: =Inputs!$D$11*(1+Inputs!$D$12)^(32-1) | AI7: =Inputs!$D$11*(1+Inputs!$D$12)^(33-1) | AJ7: =Inputs!$D$11*(1+Inputs!$D$12)^(34-1) | AK7: =Inputs!$D$11*(1+Inputs!$D$12)^(35-1) | AL7: =Inputs!$D$11*(1+Inputs!$D$12)^(36-1)
A8: Conservative | B8: Merch net revenue | C8: =IF(1<Inputs!$D$13,0,Inputs!$D$14*(1+Inputs!$D$15)^(1-Inputs!$D$13)*Inputs!$D$16) | D8: =IF(2<Inputs!$D$13,0,Inputs!$D$14*(1+Inputs!$D$15)^(2-Inputs!$D$13)*Inputs!$D$16) | E8: =IF(3<Inputs!$D$13,0,Inputs!$D$14*(1+Inputs!$D$15)^(3-Inputs!$D$13)*Inputs!$D$16) | F8: =IF(4<Inputs!$D$13,0,Inputs!$D$14*(1+Inputs!$D$15)^(4-Inputs!$D$13)*Inputs!$D$16) | G8: =IF(5<Inputs!$D$13,0,Inputs!$D$14*(1+Inputs!$D$15)^(5-Inputs!$D$13)*Inputs!$D$16) | H8: =IF(6<Inputs!$D$13,0,Inputs!$D$14*(1+Inputs!$D$15)^(6-Inputs!$D$13)*Inputs!$D$16) | I8: =IF(7<Inputs!$D$13,0,Inputs!$D$14*(1+Inputs!$D$15)^(7-Inputs!$D$13)*Inputs!$D$16) | J8: =IF(8<Inputs!$D$13,0,Inputs!$D$14*(1+Inputs!$D$15)^(8-Inputs!$D$13)*Inputs!$D$16) | K8: =IF(9<Inputs!$D$13,0,Inputs!$D$14*(1+Inputs!$D$15)^(9-Inputs!$D$13)*Inputs!$D$16) | L8: =IF(10<Inputs!$D$13,0,Inputs!$D$14*(1+Inputs!$D$15)^(10-Inputs!$D$13)*Inputs!$D$16) | M8: =IF(11<Inputs!$D$13,0,Inputs!$D$14*(1+Inputs!$D$15)^(11-Inputs!$D$13)*Inputs!$D$16) | N8: =IF(12<Inputs!$D$13,0,Inputs!$D$14*(1+Inputs!$D$15)^(12-Inputs!$D$13)*Inputs!$D$16) | O8: =IF(13<Inputs!$D$13,0,Inputs!$D$14*(1+Inputs!$D$15)^(13-Inputs!$D$13)*Inputs!$D$16) | P8: =IF(14<Inputs!$D$13,0,Inputs!$D$14*(1+Inputs!$D$15)^(14-Inputs!$D$13)*Inputs!$D$16) | Q8: =IF(15<Inputs!$D$13,0,Inputs!$D$14*(1+Inputs!$D$15)^(15-Inputs!$D$13)*Inputs!$D$16) | R8: =IF(16<Inputs!$D$13,0,Inputs!$D$14*(1+Inputs!$D$15)^(16-Inputs!$D$13)*Inputs!$D$16) | S8: =IF(17<Inputs!$D$13,0,Inputs!$D$14*(1+Inputs!$D$15)^(17-Inputs!$D$13)*Inputs!$D$16) | T8: =IF(18<Inputs!$D$13,0,Inputs!$D$14*(1+Inputs!$D$15)^(18-Inputs!$D$13)*Inputs!$D$16) | U8: =IF(19<Inputs!$D$13,0,Inputs!$D$14*(1+Inputs!$D$15)^(19-Inputs!$D$13)*Inputs!$D$16) | V8: =IF(20<Inputs!$D$13,0,Inputs!$D$14*(1+Inputs!$D$15)^(20-Inputs!$D$13)*Inputs!$D$16) | W8: =IF(21<Inputs!$D$13,0,Inputs!$D$14*(1+Inputs!$D$15)^(21-Inputs!$D$13)*Inputs!$D$16) | X8: =IF(22<Inputs!$D$13,0,Inputs!$D$14*(1+Inputs!$D$15)^(22-Inputs!$D$13)*Inputs!$D$16) | Y8: =IF(23<Inputs!$D$13,0,Inputs!$D$14*(1+Inputs!$D$15)^(23-Inputs!$D$13)*Inputs!$D$16) | Z8: =IF(24<Inputs!$D$13,0,Inputs!$D$14*(1+Inputs!$D$15)^(24-Inputs!$D$13)*Inputs!$D$16) | AA8: =IF(25<Inputs!$D$13,0,Inputs!$D$14*(1+Inputs!$D$15)^(25-Inputs!$D$13)*Inputs!$D$16) | AB8: =IF(26<Inputs!$D$13,0,Inputs!$D$14*(1+Inputs!$D$15)^(26-Inputs!$D$13)*Inputs!$D$16) | AC8: =IF(27<Inputs!$D$13,0,Inputs!$D$14*(1+Inputs!$D$15)^(27-Inputs!$D$13)*Inputs!$D$16) | AD8: =IF(28<Inputs!$D$13,0,Inputs!$D$14*(1+Inputs!$D$15)^(28-Inputs!$D$13)*Inputs!$D$16) | AE8: =IF(29<Inputs!$D$13,0,Inputs!$D$14*(1+Inputs!$D$15)^(29-Inputs!$D$13)*Inputs!$D$16) | AF8: =IF(30<Inputs!$D$13,0,Inputs!$D$14*(1+Inputs!$D$15)^(30-Inputs!$D$13)*Inputs!$D$16) | AG8: =IF(31<Inputs!$D$13,0,Inputs!$D$14*(1+Inputs!$D$15)^(31-Inputs!$D$13)*Inputs!$D$16) | AH8: =IF(32<Inputs!$D$13,0,Inputs!$D$14*(1+Inputs!$D$15)^(32-Inputs!$D$13)*Inputs!$D$16) | AI8: =IF(33<Inputs!$D$13,0,Inputs!$D$14*(1+Inputs!$D$15)^(33-Inputs!$D$13)*Inputs!$D$16) | AJ8: =IF(34<Inputs!$D$13,0,Inputs!$D$14*(1+Inputs!$D$15)^(34-Inputs!$D$13)*Inputs!$D$16) | AK8: =IF(35<Inputs!$D$13,0,Inputs!$D$14*(1+Inputs!$D$15)^(35-Inputs!$D$13)*Inputs!$D$16) | AL8: =IF(36<Inputs!$D$13,0,Inputs!$D$14*(1+Inputs!$D$15)^(36-Inputs!$D$13)*Inputs!$D$16)
A9: Conservative | B9: Operating revenue | C9: =SUM(C4,C6,C7,C8) | D9: =SUM(D4,D6,D7,D8) | E9: =SUM(E4,E6,E7,E8) | F9: =SUM(F4,F6,F7,F8) | G9: =SUM(G4,G6,G7,G8) | H9: =SUM(H4,H6,H7,H8) | I9: =SUM(I4,I6,I7,I8) | J9: =SUM(J4,J6,J7,J8) | ... AL9: =SUM(AL4,AL6,AL7,AL8)
A10: Conservative | B10: Funding inflow | C10: =IF(AND(Inputs!$D$17>0,1=Inputs!$D$17),Inputs!$D$18,0) | D10: =IF(AND(Inputs!$D$17>0,2=Inputs!$D$17),Inputs!$D$18,0) | E10: =IF(AND(Inputs!$D$17>0,3=Inputs!$D$17),Inputs!$D$18,0) | F10: =IF(AND(Inputs!$D$17>0,4=Inputs!$D$17),Inputs!$D$18,0) | G10: =IF(AND(Inputs!$D$17>0,5=Inputs!$D$17),Inputs!$D$18,0) | H10: =IF(AND(Inputs!$D$17>0,6=Inputs!$D$17),Inputs!$D$18,0) | I10: =IF(AND(Inputs!$D$17>0,7=Inputs!$D$17),Inputs!$D$18,0) | J10: =IF(AND(Inputs!$D$17>0,8=Inputs!$D$17),Inputs!$D$18,0) | K10: =IF(AND(Inputs!$D$17>0,9=Inputs!$D$17),Inputs!$D$18,0) | L10: =IF(AND(Inputs!$D$17>0,10=Inputs!$D$17),Inputs!$D$18,0) | M10: =IF(AND(Inputs!$D$17>0,11=Inputs!$D$17),Inputs!$D$18,0) | N10: =IF(AND(Inputs!$D$17>0,12=Inputs!$D$17),Inputs!$D$18,0) | O10: =IF(AND(Inputs!$D$17>0,13=Inputs!$D$17),Inputs!$D$18,0) | P10: =IF(AND(Inputs!$D$17>0,14=Inputs!$D$17),Inputs!$D$18,0) | Q10: =IF(AND(Inputs!$D$17>0,15=Inputs!$D$17),Inputs!$D$18,0) | R10: =IF(AND(Inputs!$D$17>0,16=Inputs!$D$17),Inputs!$D$18,0) | S10: =IF(AND(Inputs!$D$17>0,17=Inputs!$D$17),Inputs!$D$18,0) | T10: =IF(AND(Inputs!$D$17>0,18=Inputs!$D$17),Inputs!$D$18,0) | U10: =IF(AND(Inputs!$D$17>0,19=Inputs!$D$17),Inputs!$D$18,0) | V10: =IF(AND(Inputs!$D$17>0,20=Inputs!$D$17),Inputs!$D$18,0) | W10: =IF(AND(Inputs!$D$17>0,21=Inputs!$D$17),Inputs!$D$18,0) | X10: =IF(AND(Inputs!$D$17>0,22=Inputs!$D$17),Inputs!$D$18,0) | Y10: =IF(AND(Inputs!$D$17>0,23=Inputs!$D$17),Inputs!$D$18,0) | Z10: =IF(AND(Inputs!$D$17>0,24=Inputs!$D$17),Inputs!$D$18,0) | AA10: =IF(AND(Inputs!$D$17>0,25=Inputs!$D$17),Inputs!$D$18,0) | AB10: =IF(AND(Inputs!$D$17>0,26=Inputs!$D$17),Inputs!$D$18,0) | AC10: =IF(AND(Inputs!$D$17>0,27=Inputs!$D$17),Inputs!$D$18,0) | AD10: =IF(AND(Inputs!$D$17>0,28=Inputs!$D$17),Inputs!$D$18,0) | AE10: =IF(AND(Inputs!$D$17>0,29=Inputs!$D$17),Inputs!$D$18,0) | AF10: =IF(AND(Inputs!$D$17>0,30=Inputs!$D$17),Inputs!$D$18,0) | AG10: =IF(AND(Inputs!$D$17>0,31=Inputs!$D$17),Inputs!$D$18,0) | AH10: =IF(AND(Inputs!$D$17>0,32=Inputs!$D$17),Inputs!$D$18,0) | AI10: =IF(AND(Inputs!$D$17>0,33=Inputs!$D$17),Inputs!$D$18,0) | AJ10: =IF(AND(Inputs!$D$17>0,34=Inputs!$D$17),Inputs!$D$18,0) | AK10: =IF(AND(Inputs!$D$17>0,35=Inputs!$D$17),Inputs!$D$18,0) | AL10: =IF(AND(Inputs!$D$17>0,36=Inputs!$D$17),Inputs!$D$18,0)
A11: Conservative | B11: Payment + variable COGS | C11: =C9*Inputs!$D$26+(C4+C6+C8)*Inputs!$D$27+C2*Inputs!$D$30 | D11: =D9*Inputs!$D$26+(D4+D6+D8)*Inputs!$D$27+D2*Inputs!$D$30 | E11: =E9*Inputs!$D$26+(E4+E6+E8)*Inputs!$D$27+E2*Inputs!$D$30 | F11: =F9*Inputs!$D$26+(F4+F6+F8)*Inputs!$D$27+F2*Inputs!$D$30 | G11: =G9*Inputs!$D$26+(G4+G6+G8)*Inputs!$D$27+G2*Inputs!$D$30 | H11: =H9*Inputs!$D$26+(H4+H6+H8)*Inputs!$D$27+H2*Inputs!$D$30 | I11: =I9*Inputs!$D$26+(I4+I6+I8)*Inputs!$D$27+I2*Inputs!$D$30 | J11: =J9*Inputs!$D$26+(J4+J6+J8)*Inputs!$D$27+J2*Inputs!$D$30 | ... AL11: =AL9*Inputs!$D$26+(AL4+AL6+AL8)*Inputs!$D$27+AL2*Inputs!$D$30
A12: Conservative | B12: Partner event fees | C12: =C5*Inputs!$D$10 | D12: =D5*Inputs!$D$10 | E12: =E5*Inputs!$D$10 | F12: =F5*Inputs!$D$10 | G12: =G5*Inputs!$D$10 | H12: =H5*Inputs!$D$10 | I12: =I5*Inputs!$D$10 | J12: =J5*Inputs!$D$10 | ... AL12: =AL5*Inputs!$D$10
A13: Conservative | B13: Mission reserve (10%) | C13: =C9*Inputs!$D$29 | D13: =D9*Inputs!$D$29 | E13: =E9*Inputs!$D$29 | F13: =F9*Inputs!$D$29 | G13: =G9*Inputs!$D$29 | H13: =H9*Inputs!$D$29 | I13: =I9*Inputs!$D$29 | J13: =J9*Inputs!$D$29 | ... AL13: =AL9*Inputs!$D$29
A14: Conservative | B14: Fixed infra | C14: =Inputs!$D$19 | D14: =Inputs!$D$19 | E14: =Inputs!$D$19 | F14: =Inputs!$D$19 | G14: =Inputs!$D$19 | H14: =Inputs!$D$19 | I14: =Inputs!$D$19 | J14: =Inputs!$D$19 | ... AL14: =Inputs!$D$19
A15: Conservative | B15: AI/model/tooling | C15: =Inputs!$D$20 | D15: =Inputs!$D$20 | E15: =Inputs!$D$20 | F15: =Inputs!$D$20 | G15: =Inputs!$D$20 | H15: =Inputs!$D$20 | I15: =Inputs!$D$20 | J15: =Inputs!$D$20 | ... AL15: =Inputs!$D$20
A16: Conservative | B16: Marketing/community spend | C16: =Inputs!$D$21 | D16: =Inputs!$D$21 | E16: =Inputs!$D$21 | F16: =Inputs!$D$21 | G16: =Inputs!$D$21 | H16: =Inputs!$D$21 | I16: =Inputs!$D$21 | J16: =Inputs!$D$21 | ... AL16: =Inputs!$D$21
A17: Conservative | B17: Contractor/dev support | C17: =Inputs!$D$22 | D17: =Inputs!$D$22 | E17: =Inputs!$D$22 | F17: =Inputs!$D$22 | G17: =Inputs!$D$22 | H17: =Inputs!$D$22 | I17: =Inputs!$D$22 | J17: =Inputs!$D$22 | ... AL17: =Inputs!$D$22
A18: Conservative | B18: Compliance/legal reserve | C18: =Inputs!$D$23 | D18: =Inputs!$D$23 | E18: =Inputs!$D$23 | F18: =Inputs!$D$23 | G18: =Inputs!$D$23 | H18: =Inputs!$D$23 | I18: =Inputs!$D$23 | J18: =Inputs!$D$23 | ... AL18: =Inputs!$D$23
A19: Conservative | B19: DAO/security/legal milestone | C19: =IF(AND(Inputs!$D$24>0,1=Inputs!$D$24),Inputs!$D$25,0) | D19: =IF(AND(Inputs!$D$24>0,2=Inputs!$D$24),Inputs!$D$25,0) | E19: =IF(AND(Inputs!$D$24>0,3=Inputs!$D$24),Inputs!$D$25,0) | F19: =IF(AND(Inputs!$D$24>0,4=Inputs!$D$24),Inputs!$D$25,0) | G19: =IF(AND(Inputs!$D$24>0,5=Inputs!$D$24),Inputs!$D$25,0) | H19: =IF(AND(Inputs!$D$24>0,6=Inputs!$D$24),Inputs!$D$25,0) | I19: =IF(AND(Inputs!$D$24>0,7=Inputs!$D$24),Inputs!$D$25,0) | J19: =IF(AND(Inputs!$D$24>0,8=Inputs!$D$24),Inputs!$D$25,0) | K19: =IF(AND(Inputs!$D$24>0,9=Inputs!$D$24),Inputs!$D$25,0) | L19: =IF(AND(Inputs!$D$24>0,10=Inputs!$D$24),Inputs!$D$25,0) | M19: =IF(AND(Inputs!$D$24>0,11=Inputs!$D$24),Inputs!$D$25,0) | N19: =IF(AND(Inputs!$D$24>0,12=Inputs!$D$24),Inputs!$D$25,0) | O19: =IF(AND(Inputs!$D$24>0,13=Inputs!$D$24),Inputs!$D$25,0) | P19: =IF(AND(Inputs!$D$24>0,14=Inputs!$D$24),Inputs!$D$25,0) | Q19: =IF(AND(Inputs!$D$24>0,15=Inputs!$D$24),Inputs!$D$25,0) | R19: =IF(AND(Inputs!$D$24>0,16=Inputs!$D$24),Inputs!$D$25,0) | S19: =IF(AND(Inputs!$D$24>0,17=Inputs!$D$24),Inputs!$D$25,0) | T19: =IF(AND(Inputs!$D$24>0,18=Inputs!$D$24),Inputs!$D$25,0) | U19: =IF(AND(Inputs!$D$24>0,19=Inputs!$D$24),Inputs!$D$25,0) | V19: =IF(AND(Inputs!$D$24>0,20=Inputs!$D$24),Inputs!$D$25,0) | W19: =IF(AND(Inputs!$D$24>0,21=Inputs!$D$24),Inputs!$D$25,0) | X19: =IF(AND(Inputs!$D$24>0,22=Inputs!$D$24),Inputs!$D$25,0) | Y19: =IF(AND(Inputs!$D$24>0,23=Inputs!$D$24),Inputs!$D$25,0) | Z19: =IF(AND(Inputs!$D$24>0,24=Inputs!$D$24),Inputs!$D$25,0) | AA19: =IF(AND(Inputs!$D$24>0,25=Inputs!$D$24),Inputs!$D$25,0) | AB19: =IF(AND(Inputs!$D$24>0,26=Inputs!$D$24),Inputs!$D$25,0) | AC19: =IF(AND(Inputs!$D$24>0,27=Inputs!$D$24),Inputs!$D$25,0) | AD19: =IF(AND(Inputs!$D$24>0,28=Inputs!$D$24),Inputs!$D$25,0) | AE19: =IF(AND(Inputs!$D$24>0,29=Inputs!$D$24),Inputs!$D$25,0) | AF19: =IF(AND(Inputs!$D$24>0,30=Inputs!$D$24),Inputs!$D$25,0) | AG19: =IF(AND(Inputs!$D$24>0,31=Inputs!$D$24),Inputs!$D$25,0) | AH19: =IF(AND(Inputs!$D$24>0,32=Inputs!$D$24),Inputs!$D$25,0) | AI19: =IF(AND(Inputs!$D$24>0,33=Inputs!$D$24),Inputs!$D$25,0) | AJ19: =IF(AND(Inputs!$D$24>0,34=Inputs!$D$24),Inputs!$D$25,0) | AK19: =IF(AND(Inputs!$D$24>0,35=Inputs!$D$24),Inputs!$D$25,0) | AL19: =IF(AND(Inputs!$D$24>0,36=Inputs!$D$24),Inputs!$D$25,0)
A20: Conservative | B20: Tax planning reserve | C20: =MAX((C9-C11-C12-C13-C14-C15-C16-C17-C18-C19),0)*Inputs!$D$28 | D20: =MAX((D9-D11-D12-D13-D14-D15-D16-D17-D18-D19),0)*Inputs!$D$28 | E20: =MAX((E9-E11-E12-E13-E14-E15-E16-E17-E18-E19),0)*Inputs!$D$28 | F20: =MAX((F9-F11-F12-F13-F14-F15-F16-F17-F18-F19),0)*Inputs!$D$28 | G20: =MAX((G9-G11-G12-G13-G14-G15-G16-G17-G18-G19),0)*Inputs!$D$28 | H20: =MAX((H9-H11-H12-H13-H14-H15-H16-H17-H18-H19),0)*Inputs!$D$28 | I20: =MAX((I9-I11-I12-I13-I14-I15-I16-I17-I18-I19),0)*Inputs!$D$28 | J20: =MAX((J9-J11-J12-J13-J14-J15-J16-J17-J18-J19),0)*Inputs!$D$28 | ... AL20: =MAX((AL9-AL11-AL12-AL13-AL14-AL15-AL16-AL17-AL18-AL19),0)*Inputs!$D$28
A21: Conservative | B21: Total cash out/reserves | C21: =SUM(C11:C20) | D21: =SUM(D11:D20) | E21: =SUM(E11:E20) | F21: =SUM(F11:F20) | G21: =SUM(G11:G20) | H21: =SUM(H11:H20) | I21: =SUM(I11:I20) | J21: =SUM(J11:J20) | ... AL21: =SUM(AL11:AL20)
A22: Conservative | B22: Operating net cash flow | C22: =C9-C21 | D22: =D9-D21 | E22: =E9-E21 | F22: =F9-F21 | G22: =G9-G21 | H22: =H9-H21 | I22: =I9-I21 | J22: =J9-J21 | ... AL22: =AL9-AL21
A23: Conservative | B23: Net cash flow incl. funding | C23: =C22+C10 | D23: =D22+D10 | E23: =E22+E10 | F23: =F22+F10 | G23: =G22+G10 | H23: =H22+H10 | I23: =I22+I10 | J23: =J22+J10 | ... AL23: =AL22+AL10
A24: Conservative | B24: Cumulative cash | C24: =Inputs!$D$2+C23 | D24: =C24+D23 | E24: =D24+E23 | F24: =E24+F23 | G24: =F24+G23 | H24: =G24+H23 | I24: =H24+I23 | J24: =I24+J23 | K24: =J24+K23 | ... AL24: =AK24+AL23
A25: Conservative | B25: Runway status | C25: =IF(C24<0,"OUT","OK") | D25: =IF(D24<0,"OUT","OK") | E25: =IF(E24<0,"OUT","OK") | F25: =IF(F24<0,"OUT","OK") | G25: =IF(G24<0,"OUT","OK") | H25: =IF(H24<0,"OUT","OK") | I25: =IF(I24<0,"OUT","OK") | J25: =IF(J24<0,"OUT","OK") | ... AL25: =IF(AL24<0,"OUT","OK")
A27: Base | B27: Active members | C27: =Inputs!$E$3*(1+Inputs!$E$4)^(1-1) | D27: =Inputs!$E$3*(1+Inputs!$E$4)^(2-1) | E27: =Inputs!$E$3*(1+Inputs!$E$4)^(3-1) | F27: =Inputs!$E$3*(1+Inputs!$E$4)^(4-1) | G27: =Inputs!$E$3*(1+Inputs!$E$4)^(5-1) | H27: =Inputs!$E$3*(1+Inputs!$E$4)^(6-1) | I27: =Inputs!$E$3*(1+Inputs!$E$4)^(7-1) | J27: =Inputs!$E$3*(1+Inputs!$E$4)^(8-1) | K27: =Inputs!$E$3*(1+Inputs!$E$4)^(9-1) | L27: =Inputs!$E$3*(1+Inputs!$E$4)^(10-1) | M27: =Inputs!$E$3*(1+Inputs!$E$4)^(11-1) | N27: =Inputs!$E$3*(1+Inputs!$E$4)^(12-1) | O27: =Inputs!$E$3*(1+Inputs!$E$4)^(13-1) | P27: =Inputs!$E$3*(1+Inputs!$E$4)^(14-1) | Q27: =Inputs!$E$3*(1+Inputs!$E$4)^(15-1) | R27: =Inputs!$E$3*(1+Inputs!$E$4)^(16-1) | S27: =Inputs!$E$3*(1+Inputs!$E$4)^(17-1) | T27: =Inputs!$E$3*(1+Inputs!$E$4)^(18-1) | U27: =Inputs!$E$3*(1+Inputs!$E$4)^(19-1) | V27: =Inputs!$E$3*(1+Inputs!$E$4)^(20-1) | W27: =Inputs!$E$3*(1+Inputs!$E$4)^(21-1) | X27: =Inputs!$E$3*(1+Inputs!$E$4)^(22-1) | Y27: =Inputs!$E$3*(1+Inputs!$E$4)^(23-1) | Z27: =Inputs!$E$3*(1+Inputs!$E$4)^(24-1) | AA27: =Inputs!$E$3*(1+Inputs!$E$4)^(25-1) | AB27: =Inputs!$E$3*(1+Inputs!$E$4)^(26-1) | AC27: =Inputs!$E$3*(1+Inputs!$E$4)^(27-1) | AD27: =Inputs!$E$3*(1+Inputs!$E$4)^(28-1) | AE27: =Inputs!$E$3*(1+Inputs!$E$4)^(29-1) | AF27: =Inputs!$E$3*(1+Inputs!$E$4)^(30-1) | AG27: =Inputs!$E$3*(1+Inputs!$E$4)^(31-1) | AH27: =Inputs!$E$3*(1+Inputs!$E$4)^(32-1) | AI27: =Inputs!$E$3*(1+Inputs!$E$4)^(33-1) | AJ27: =Inputs!$E$3*(1+Inputs!$E$4)^(34-1) | AK27: =Inputs!$E$3*(1+Inputs!$E$4)^(35-1) | AL27: =Inputs!$E$3*(1+Inputs!$E$4)^(36-1)
A28: Base | B28: Paid members | C28: =C27*Inputs!$E$5 | D28: =D27*Inputs!$E$5 | E28: =E27*Inputs!$E$5 | F28: =F27*Inputs!$E$5 | G28: =G27*Inputs!$E$5 | H28: =H27*Inputs!$E$5 | I28: =I27*Inputs!$E$5 | J28: =J27*Inputs!$E$5 | ... AL28: =AL27*Inputs!$E$5
A29: Base | B29: Membership revenue | C29: =C28*Inputs!$E$6 | D29: =D28*Inputs!$E$6 | E29: =E28*Inputs!$E$6 | F29: =F28*Inputs!$E$6 | G29: =G28*Inputs!$E$6 | H29: =H28*Inputs!$E$6 | I29: =I28*Inputs!$E$6 | J29: =J28*Inputs!$E$6 | ... AL29: =AL28*Inputs!$E$6
A30: Base | B30: Collaborative events | C30: =Inputs!$E$7*(1+Inputs!$E$8)^(1-1) | D30: =Inputs!$E$7*(1+Inputs!$E$8)^(2-1) | E30: =Inputs!$E$7*(1+Inputs!$E$8)^(3-1) | F30: =Inputs!$E$7*(1+Inputs!$E$8)^(4-1) | G30: =Inputs!$E$7*(1+Inputs!$E$8)^(5-1) | H30: =Inputs!$E$7*(1+Inputs!$E$8)^(6-1) | I30: =Inputs!$E$7*(1+Inputs!$E$8)^(7-1) | J30: =Inputs!$E$7*(1+Inputs!$E$8)^(8-1) | K30: =Inputs!$E$7*(1+Inputs!$E$8)^(9-1) | L30: =Inputs!$E$7*(1+Inputs!$E$8)^(10-1) | M30: =Inputs!$E$7*(1+Inputs!$E$8)^(11-1) | N30: =Inputs!$E$7*(1+Inputs!$E$8)^(12-1) | O30: =Inputs!$E$7*(1+Inputs!$E$8)^(13-1) | P30: =Inputs!$E$7*(1+Inputs!$E$8)^(14-1) | Q30: =Inputs!$E$7*(1+Inputs!$E$8)^(15-1) | R30: =Inputs!$E$7*(1+Inputs!$E$8)^(16-1) | S30: =Inputs!$E$7*(1+Inputs!$E$8)^(17-1) | T30: =Inputs!$E$7*(1+Inputs!$E$8)^(18-1) | U30: =Inputs!$E$7*(1+Inputs!$E$8)^(19-1) | V30: =Inputs!$E$7*(1+Inputs!$E$8)^(20-1) | W30: =Inputs!$E$7*(1+Inputs!$E$8)^(21-1) | X30: =Inputs!$E$7*(1+Inputs!$E$8)^(22-1) | Y30: =Inputs!$E$7*(1+Inputs!$E$8)^(23-1) | Z30: =Inputs!$E$7*(1+Inputs!$E$8)^(24-1) | AA30: =Inputs!$E$7*(1+Inputs!$E$8)^(25-1) | AB30: =Inputs!$E$7*(1+Inputs!$E$8)^(26-1) | AC30: =Inputs!$E$7*(1+Inputs!$E$8)^(27-1) | AD30: =Inputs!$E$7*(1+Inputs!$E$8)^(28-1) | AE30: =Inputs!$E$7*(1+Inputs!$E$8)^(29-1) | AF30: =Inputs!$E$7*(1+Inputs!$E$8)^(30-1) | AG30: =Inputs!$E$7*(1+Inputs!$E$8)^(31-1) | AH30: =Inputs!$E$7*(1+Inputs!$E$8)^(32-1) | AI30: =Inputs!$E$7*(1+Inputs!$E$8)^(33-1) | AJ30: =Inputs!$E$7*(1+Inputs!$E$8)^(34-1) | AK30: =Inputs!$E$7*(1+Inputs!$E$8)^(35-1) | AL30: =Inputs!$E$7*(1+Inputs!$E$8)^(36-1)
A31: Base | B31: Event revenue | C31: =C30*Inputs!$E$9 | D31: =D30*Inputs!$E$9 | E31: =E30*Inputs!$E$9 | F31: =F30*Inputs!$E$9 | G31: =G30*Inputs!$E$9 | H31: =H30*Inputs!$E$9 | I31: =I30*Inputs!$E$9 | J31: =J30*Inputs!$E$9 | ... AL31: =AL30*Inputs!$E$9
A32: Base | B32: Automation/services revenue | C32: =Inputs!$E$11*(1+Inputs!$E$12)^(1-1) | D32: =Inputs!$E$11*(1+Inputs!$E$12)^(2-1) | E32: =Inputs!$E$11*(1+Inputs!$E$12)^(3-1) | F32: =Inputs!$E$11*(1+Inputs!$E$12)^(4-1) | G32: =Inputs!$E$11*(1+Inputs!$E$12)^(5-1) | H32: =Inputs!$E$11*(1+Inputs!$E$12)^(6-1) | I32: =Inputs!$E$11*(1+Inputs!$E$12)^(7-1) | J32: =Inputs!$E$11*(1+Inputs!$E$12)^(8-1) | K32: =Inputs!$E$11*(1+Inputs!$E$12)^(9-1) | L32: =Inputs!$E$11*(1+Inputs!$E$12)^(10-1) | M32: =Inputs!$E$11*(1+Inputs!$E$12)^(11-1) | N32: =Inputs!$E$11*(1+Inputs!$E$12)^(12-1) | O32: =Inputs!$E$11*(1+Inputs!$E$12)^(13-1) | P32: =Inputs!$E$11*(1+Inputs!$E$12)^(14-1) | Q32: =Inputs!$E$11*(1+Inputs!$E$12)^(15-1) | R32: =Inputs!$E$11*(1+Inputs!$E$12)^(16-1) | S32: =Inputs!$E$11*(1+Inputs!$E$12)^(17-1) | T32: =Inputs!$E$11*(1+Inputs!$E$12)^(18-1) | U32: =Inputs!$E$11*(1+Inputs!$E$12)^(19-1) | V32: =Inputs!$E$11*(1+Inputs!$E$12)^(20-1) | W32: =Inputs!$E$11*(1+Inputs!$E$12)^(21-1) | X32: =Inputs!$E$11*(1+Inputs!$E$12)^(22-1) | Y32: =Inputs!$E$11*(1+Inputs!$E$12)^(23-1) | Z32: =Inputs!$E$11*(1+Inputs!$E$12)^(24-1) | AA32: =Inputs!$E$11*(1+Inputs!$E$12)^(25-1) | AB32: =Inputs!$E$11*(1+Inputs!$E$12)^(26-1) | AC32: =Inputs!$E$11*(1+Inputs!$E$12)^(27-1) | AD32: =Inputs!$E$11*(1+Inputs!$E$12)^(28-1) | AE32: =Inputs!$E$11*(1+Inputs!$E$12)^(29-1) | AF32: =Inputs!$E$11*(1+Inputs!$E$12)^(30-1) | AG32: =Inputs!$E$11*(1+Inputs!$E$12)^(31-1) | AH32: =Inputs!$E$11*(1+Inputs!$E$12)^(32-1) | AI32: =Inputs!$E$11*(1+Inputs!$E$12)^(33-1) | AJ32: =Inputs!$E$11*(1+Inputs!$E$12)^(34-1) | AK32: =Inputs!$E$11*(1+Inputs!$E$12)^(35-1) | AL32: =Inputs!$E$11*(1+Inputs!$E$12)^(36-1)
A33: Base | B33: Merch net revenue | C33: =IF(1<Inputs!$E$13,0,Inputs!$E$14*(1+Inputs!$E$15)^(1-Inputs!$E$13)*Inputs!$E$16) | D33: =IF(2<Inputs!$E$13,0,Inputs!$E$14*(1+Inputs!$E$15)^(2-Inputs!$E$13)*Inputs!$E$16) | E33: =IF(3<Inputs!$E$13,0,Inputs!$E$14*(1+Inputs!$E$15)^(3-Inputs!$E$13)*Inputs!$E$16) | F33: =IF(4<Inputs!$E$13,0,Inputs!$E$14*(1+Inputs!$E$15)^(4-Inputs!$E$13)*Inputs!$E$16) | G33: =IF(5<Inputs!$E$13,0,Inputs!$E$14*(1+Inputs!$E$15)^(5-Inputs!$E$13)*Inputs!$E$16) | H33: =IF(6<Inputs!$E$13,0,Inputs!$E$14*(1+Inputs!$E$15)^(6-Inputs!$E$13)*Inputs!$E$16) | I33: =IF(7<Inputs!$E$13,0,Inputs!$E$14*(1+Inputs!$E$15)^(7-Inputs!$E$13)*Inputs!$E$16) | J33: =IF(8<Inputs!$E$13,0,Inputs!$E$14*(1+Inputs!$E$15)^(8-Inputs!$E$13)*Inputs!$E$16) | K33: =IF(9<Inputs!$E$13,0,Inputs!$E$14*(1+Inputs!$E$15)^(9-Inputs!$E$13)*Inputs!$E$16) | L33: =IF(10<Inputs!$E$13,0,Inputs!$E$14*(1+Inputs!$E$15)^(10-Inputs!$E$13)*Inputs!$E$16) | M33: =IF(11<Inputs!$E$13,0,Inputs!$E$14*(1+Inputs!$E$15)^(11-Inputs!$E$13)*Inputs!$E$16) | N33: =IF(12<Inputs!$E$13,0,Inputs!$E$14*(1+Inputs!$E$15)^(12-Inputs!$E$13)*Inputs!$E$16) | O33: =IF(13<Inputs!$E$13,0,Inputs!$E$14*(1+Inputs!$E$15)^(13-Inputs!$E$13)*Inputs!$E$16) | P33: =IF(14<Inputs!$E$13,0,Inputs!$E$14*(1+Inputs!$E$15)^(14-Inputs!$E$13)*Inputs!$E$16) | Q33: =IF(15<Inputs!$E$13,0,Inputs!$E$14*(1+Inputs!$E$15)^(15-Inputs!$E$13)*Inputs!$E$16) | R33: =IF(16<Inputs!$E$13,0,Inputs!$E$14*(1+Inputs!$E$15)^(16-Inputs!$E$13)*Inputs!$E$16) | S33: =IF(17<Inputs!$E$13,0,Inputs!$E$14*(1+Inputs!$E$15)^(17-Inputs!$E$13)*Inputs!$E$16) | T33: =IF(18<Inputs!$E$13,0,Inputs!$E$14*(1+Inputs!$E$15)^(18-Inputs!$E$13)*Inputs!$E$16) | U33: =IF(19<Inputs!$E$13,0,Inputs!$E$14*(1+Inputs!$E$15)^(19-Inputs!$E$13)*Inputs!$E$16) | V33: =IF(20<Inputs!$E$13,0,Inputs!$E$14*(1+Inputs!$E$15)^(20-Inputs!$E$13)*Inputs!$E$16) | W33: =IF(21<Inputs!$E$13,0,Inputs!$E$14*(1+Inputs!$E$15)^(21-Inputs!$E$13)*Inputs!$E$16) | X33: =IF(22<Inputs!$E$13,0,Inputs!$E$14*(1+Inputs!$E$15)^(22-Inputs!$E$13)*Inputs!$E$16) | Y33: =IF(23<Inputs!$E$13,0,Inputs!$E$14*(1+Inputs!$E$15)^(23-Inputs!$E$13)*Inputs!$E$16) | Z33: =IF(24<Inputs!$E$13,0,Inputs!$E$14*(1+Inputs!$E$15)^(24-Inputs!$E$13)*Inputs!$E$16) | AA33: =IF(25<Inputs!$E$13,0,Inputs!$E$14*(1+Inputs!$E$15)^(25-Inputs!$E$13)*Inputs!$E$16) | AB33: =IF(26<Inputs!$E$13,0,Inputs!$E$14*(1+Inputs!$E$15)^(26-Inputs!$E$13)*Inputs!$E$16) | AC33: =IF(27<Inputs!$E$13,0,Inputs!$E$14*(1+Inputs!$E$15)^(27-Inputs!$E$13)*Inputs!$E$16) | AD33: =IF(28<Inputs!$E$13,0,Inputs!$E$14*(1+Inputs!$E$15)^(28-Inputs!$E$13)*Inputs!$E$16) | AE33: =IF(29<Inputs!$E$13,0,Inputs!$E$14*(1+Inputs!$E$15)^(29-Inputs!$E$13)*Inputs!$E$16) | AF33: =IF(30<Inputs!$E$13,0,Inputs!$E$14*(1+Inputs!$E$15)^(30-Inputs!$E$13)*Inputs!$E$16) | AG33: =IF(31<Inputs!$E$13,0,Inputs!$E$14*(1+Inputs!$E$15)^(31-Inputs!$E$13)*Inputs!$E$16) | AH33: =IF(32<Inputs!$E$13,0,Inputs!$E$14*(1+Inputs!$E$15)^(32-Inputs!$E$13)*Inputs!$E$16) | AI33: =IF(33<Inputs!$E$13,0,Inputs!$E$14*(1+Inputs!$E$15)^(33-Inputs!$E$13)*Inputs!$E$16) | AJ33: =IF(34<Inputs!$E$13,0,Inputs!$E$14*(1+Inputs!$E$15)^(34-Inputs!$E$13)*Inputs!$E$16) | AK33: =IF(35<Inputs!$E$13,0,Inputs!$E$14*(1+Inputs!$E$15)^(35-Inputs!$E$13)*Inputs!$E$16) | AL33: =IF(36<Inputs!$E$13,0,Inputs!$E$14*(1+Inputs!$E$15)^(36-Inputs!$E$13)*Inputs!$E$16)
A34: Base | B34: Operating revenue | C34: =SUM(C29,C31,C32,C33) | D34: =SUM(D29,D31,D32,D33) | E34: =SUM(E29,E31,E32,E33) | F34: =SUM(F29,F31,F32,F33) | G34: =SUM(G29,G31,G32,G33) | H34: =SUM(H29,H31,H32,H33) | I34: =SUM(I29,I31,I32,I33) | J34: =SUM(J29,J31,J32,J33) | ... AL34: =SUM(AL29,AL31,AL32,AL33)
A35: Base | B35: Funding inflow | C35: =IF(AND(Inputs!$E$17>0,1=Inputs!$E$17),Inputs!$E$18,0) | D35: =IF(AND(Inputs!$E$17>0,2=Inputs!$E$17),Inputs!$E$18,0) | E35: =IF(AND(Inputs!$E$17>0,3=Inputs!$E$17),Inputs!$E$18,0) | F35: =IF(AND(Inputs!$E$17>0,4=Inputs!$E$17),Inputs!$E$18,0) | G35: =IF(AND(Inputs!$E$17>0,5=Inputs!$E$17),Inputs!$E$18,0) | H35: =IF(AND(Inputs!$E$17>0,6=Inputs!$E$17),Inputs!$E$18,0) | I35: =IF(AND(Inputs!$E$17>0,7=Inputs!$E$17),Inputs!$E$18,0) | J35: =IF(AND(Inputs!$E$17>0,8=Inputs!$E$17),Inputs!$E$18,0) | K35: =IF(AND(Inputs!$E$17>0,9=Inputs!$E$17),Inputs!$E$18,0) | L35: =IF(AND(Inputs!$E$17>0,10=Inputs!$E$17),Inputs!$E$18,0) | M35: =IF(AND(Inputs!$E$17>0,11=Inputs!$E$17),Inputs!$E$18,0) | N35: =IF(AND(Inputs!$E$17>0,12=Inputs!$E$17),Inputs!$E$18,0) | O35: =IF(AND(Inputs!$E$17>0,13=Inputs!$E$17),Inputs!$E$18,0) | P35: =IF(AND(Inputs!$E$17>0,14=Inputs!$E$17),Inputs!$E$18,0) | Q35: =IF(AND(Inputs!$E$17>0,15=Inputs!$E$17),Inputs!$E$18,0) | R35: =IF(AND(Inputs!$E$17>0,16=Inputs!$E$17),Inputs!$E$18,0) | S35: =IF(AND(Inputs!$E$17>0,17=Inputs!$E$17),Inputs!$E$18,0) | T35: =IF(AND(Inputs!$E$17>0,18=Inputs!$E$17),Inputs!$E$18,0) | U35: =IF(AND(Inputs!$E$17>0,19=Inputs!$E$17),Inputs!$E$18,0) | V35: =IF(AND(Inputs!$E$17>0,20=Inputs!$E$17),Inputs!$E$18,0) | W35: =IF(AND(Inputs!$E$17>0,21=Inputs!$E$17),Inputs!$E$18,0) | X35: =IF(AND(Inputs!$E$17>0,22=Inputs!$E$17),Inputs!$E$18,0) | Y35: =IF(AND(Inputs!$E$17>0,23=Inputs!$E$17),Inputs!$E$18,0) | Z35: =IF(AND(Inputs!$E$17>0,24=Inputs!$E$17),Inputs!$E$18,0) | AA35: =IF(AND(Inputs!$E$17>0,25=Inputs!$E$17),Inputs!$E$18,0) | AB35: =IF(AND(Inputs!$E$17>0,26=Inputs!$E$17),Inputs!$E$18,0) | AC35: =IF(AND(Inputs!$E$17>0,27=Inputs!$E$17),Inputs!$E$18,0) | AD35: =IF(AND(Inputs!$E$17>0,28=Inputs!$E$17),Inputs!$E$18,0) | AE35: =IF(AND(Inputs!$E$17>0,29=Inputs!$E$17),Inputs!$E$18,0) | AF35: =IF(AND(Inputs!$E$17>0,30=Inputs!$E$17),Inputs!$E$18,0) | AG35: =IF(AND(Inputs!$E$17>0,31=Inputs!$E$17),Inputs!$E$18,0) | AH35: =IF(AND(Inputs!$E$17>0,32=Inputs!$E$17),Inputs!$E$18,0) | AI35: =IF(AND(Inputs!$E$17>0,33=Inputs!$E$17),Inputs!$E$18,0) | AJ35: =IF(AND(Inputs!$E$17>0,34=Inputs!$E$17),Inputs!$E$18,0) | AK35: =IF(AND(Inputs!$E$17>0,35=Inputs!$E$17),Inputs!$E$18,0) | AL35: =IF(AND(Inputs!$E$17>0,36=Inputs!$E$17),Inputs!$E$18,0)
A36: Base | B36: Payment + variable COGS | C36: =C34*Inputs!$E$26+(C29+C31+C33)*Inputs!$E$27+C27*Inputs!$E$30 | D36: =D34*Inputs!$E$26+(D29+D31+D33)*Inputs!$E$27+D27*Inputs!$E$30 | E36: =E34*Inputs!$E$26+(E29+E31+E33)*Inputs!$E$27+E27*Inputs!$E$30 | F36: =F34*Inputs!$E$26+(F29+F31+F33)*Inputs!$E$27+F27*Inputs!$E$30 | G36: =G34*Inputs!$E$26+(G29+G31+G33)*Inputs!$E$27+G27*Inputs!$E$30 | H36: =H34*Inputs!$E$26+(H29+H31+H33)*Inputs!$E$27+H27*Inputs!$E$30 | I36: =I34*Inputs!$E$26+(I29+I31+I33)*Inputs!$E$27+I27*Inputs!$E$30 | J36: =J34*Inputs!$E$26+(J29+J31+J33)*Inputs!$E$27+J27*Inputs!$E$30 | ... AL36: =AL34*Inputs!$E$26+(AL29+AL31+AL33)*Inputs!$E$27+AL27*Inputs!$E$30
A37: Base | B37: Partner event fees | C37: =C30*Inputs!$E$10 | D37: =D30*Inputs!$E$10 | E37: =E30*Inputs!$E$10 | F37: =F30*Inputs!$E$10 | G37: =G30*Inputs!$E$10 | H37: =H30*Inputs!$E$10 | I37: =I30*Inputs!$E$10 | J37: =J30*Inputs!$E$10 | ... AL37: =AL30*Inputs!$E$10
A38: Base | B38: Mission reserve (10%) | C38: =C34*Inputs!$E$29 | D38: =D34*Inputs!$E$29 | E38: =E34*Inputs!$E$29 | F38: =F34*Inputs!$E$29 | G38: =G34*Inputs!$E$29 | H38: =H34*Inputs!$E$29 | I38: =I34*Inputs!$E$29 | J38: =J34*Inputs!$E$29 | ... AL38: =AL34*Inputs!$E$29
A39: Base | B39: Fixed infra | C39: =Inputs!$E$19 | D39: =Inputs!$E$19 | E39: =Inputs!$E$19 | F39: =Inputs!$E$19 | G39: =Inputs!$E$19 | H39: =Inputs!$E$19 | I39: =Inputs!$E$19 | J39: =Inputs!$E$19 | ... AL39: =Inputs!$E$19
A40: Base | B40: AI/model/tooling | C40: =Inputs!$E$20 | D40: =Inputs!$E$20 | E40: =Inputs!$E$20 | F40: =Inputs!$E$20 | G40: =Inputs!$E$20 | H40: =Inputs!$E$20 | I40: =Inputs!$E$20 | J40: =Inputs!$E$20 | ... AL40: =Inputs!$E$20
A41: Base | B41: Marketing/community spend | C41: =Inputs!$E$21 | D41: =Inputs!$E$21 | E41: =Inputs!$E$21 | F41: =Inputs!$E$21 | G41: =Inputs!$E$21 | H41: =Inputs!$E$21 | I41: =Inputs!$E$21 | J41: =Inputs!$E$21 | ... AL41: =Inputs!$E$21
...

Sheet Sensitivity
A1: Assumption tested | B1: Case | C1: Multiplier / override | D1: Ending cash formula | E1: Cash-out month formula | F1: Break-even month formula | G1: M01 | H1: M02 | I1: M03 | J1: M04 | K1: M05 | L1: M06 | M1: M07 | N1: M08 | O1: M09 | P1: M10 | Q1: M11 | R1: M12 | S1: M13 | T1: M14 | U1: M15 | V1: M16 | W1: M17 | X1: M18 | Y1: M19 | Z1: M20 | AA1: M21 | AB1: M22 | AC1: M23 | AD1: M24 | AE1: M25 | AF1: M26 | AG1: M27 | AH1: M28 | AI1: M29 | AJ1: M30 | AK1: M31 | AL1: M32 | AM1: M33 | AN1: M34 | AO1: M35 | AP1: M36
